Workbook

Sheet Test Cases
A1: TC ID | B1: Module | C1: Type | D1: Priority | E1: Test Scenario | F1: Preconditions | G1: Test Steps | H1: Test Data | I1: Expected Result | J1: Actual Result | K1: Status | L1: Notes
A2: TC-001 | B2: Add Book | C2: Positive | D2: High | E2: Tambah buku dengan data valid via API | F2: Backend berjalan | G2: POST /api/books | H2: {"title":"Atomic Habits","author":"James Clear","status":"unread"} | I2: Status 201, response berisi objek buku baru dengan id | J2: 201 Created, id:9, field cover/genre/pages/rating default kosong/0 | K2: Pass
A3: TC-002 | B3: Add Book | C3: Positive | D3: Medium | E3: Tambah buku dengan status reading | F3: Backend berjalan | G3: POST /api/books | H3: status="reading" | I3: Status 201, tersimpan dengan status reading | J3: 201 Created, id:10, status reading | K3: Pass
A4: TC-003 | B4: Add Book | C4: Positive | D4: Medium | E4: Tambah buku dengan status completed | F4: Backend berjalan | G4: POST /api/books | H4: status="completed" | I4: Status 201, tersimpan dengan status completed | J4: 201 Created, id:11, status read | K4: Pass
A5: TC-004 | B5: Add Book | C5: Negative | D5: High | E5: Tambah buku tanpa field title | F5: Backend berjalan | G5: POST /api/books | H5: {"author":"James Clear","status":"unread"} | I5: Ditolak (400) dengan pesan error yang jelas | J5: 201 Created (harusnya 400), id:12 dibuat dengan title:null | K5: Fail
A6: TC-005 | B6: Add Book | C6: Negative | D6: High | E6: Tambah buku tanpa field author | F6: Backend berjalan | G6: POST /api/books | H6: {"title":"Atomic Habits","status":"unread"} | I6: Ditolak (400) dengan pesan error yang jelas | J6: 201 Created (harusnya 400), author:null | K6: Fail
A7: TC-006 | B7: Add Book | C7: Negative | D7: Medium | E7: Tambah buku tanpa field status | F7: Backend berjalan | G7: POST /api/books | H7: tanpa field status | I7: Ditolak (400) atau default ke unread - dokumentasikan perilaku aktual | J7: 201 Created, status default ke "want-to-read" saat tidak dikirim | K7: Pass
A8: TC-007 | B8: Add Book | C8: Negative | D8: High | E8: Tambah buku dengan status tidak valid | F8: Backend berjalan | G8: POST /api/books | H8: status="finished" | I8: Ditolak (400), tidak diterima sebagai enum valid | J8: 201 Created (harusnya 400), status:"finished" tersimpan | K8: Fail
A9: TC-008 | B9: Add Book | C9: Negative | D9: Medium | E9: Tambah buku dengan title string kosong | F9: Backend berjalan | G9: POST /api/books | H9: title="" | I9: Ditolak (400) | J9: 201 Created (harusnya 400), title:"" | K9: Fail
A10: TC-009 | B10: Add Book | C10: Negative | D10: Low | E10: Tambah buku dengan title sangat panjang | F10: Backend berjalan | G10: POST /api/books | H10: title 1000+ karakter | I10: Server tidak crash; ditolak atau diterima sesuai batas wajar | J10: 201 Created, tidak crash meski title >1000 karakter | K10: Pass | L10: Tidak ada batas maksimal panjang title pertimbangkan validasi max length sebagai improvement
A11: TC-010 | B11: Add Book | C11: Negative | D11: Medium | E11: Tambah buku dengan tipe data salah | F11: Backend berjalan | G11: POST /api/books | H11: title=12345 (number) | I11: Ditolak (400) atau dikonversi aman, tidak 500 error | J11: 201 Created, title tersimpan sebagai number (12345) bukan string, tidak ada validasi/konversi tipe | K11: Fail
A12: TC-011 | B12: Add Book | C12: Negative | D12: Low | E12: Tambah buku dengan field tambahan tak dikenal | F12: Backend berjalan | G12: POST /api/books | H12: tambahkan "rating":5 | I12: Diabaikan atau ditolak, bukan 500 error | J12: 201 Created, field "foo" diabaikan, tidak muncul di response | K12: Pass
A13: TC-012 | B13: Add Book | C13: Positive | D13: High | E13: Tambah buku via form UI dengan data valid | F13: Frontend & backend berjalan | G13: Isi form Add Book, submit | H13: Title, Author valid | I13: Buku baru langsung muncul di daftar | J13: 201 Created, title tersimpan sebagai string apa adanya | K13: Blocked | L13: Tidak ada form UI untuk menambah buku baru dengan title/author custom — fitur Add Book hanya tersedia via API. Tombol "+" di UI berfungsi untuk menambahkan buku existing (status want-to-read) ke My Library, bukan membuat buku baru.
A14: TC-013 | B14: Add Book | C14: Negative | D14: High | E14: Submit form Add dengan title kosong | F14: Frontend berjalan | G14: Kosongkan title, submit | H14: title="" | I14: Validasi frontend mencegah submit / pesan error muncul | K14: Blocked | L14: Tidak ada form UI untuk menambah buku baru dengan title/author custom — fitur Add Book hanya tersedia via API. Tombol "+" di UI berfungsi untuk menambahkan buku existing (status want-to-read) ke My Library, bukan membuat buku baru.
A15: TC-014 | B15: Add Book | C15: Negative | D15: High | E15: Submit form Add dengan author kosong | F15: Frontend berjalan | G15: Kosongkan author, submit | H15: author="" | I15: Validasi frontend mencegah submit / pesan error muncul | K15: Blocked | L15: Tidak ada form UI untuk menambah buku baru dengan title/author custom — fitur Add Book hanya tersedia via API. Tombol "+" di UI berfungsi untuk menambahkan buku existing (status want-to-read) ke My Library, bukan membuat buku baru.
A16: TC-015 | B16: Add Book | C16: Negative | D16: Medium | E16: Tambah buku dengan script pada title (XSS check) | F16: Frontend berjalan | G16: Isi title dengan <script>alert(1)</script> | H16: title berisi script tag | I16: Ditampilkan sebagai teks biasa, script tidak tereksekusi | J16: Title tampil sebagai teks literal di UI, script tidak tereksekusi, tidak ada popup alert | K16: Pass
A17: TC-016 | B17: View/List | C17: Positive | D17: High | E17: Ambil semua buku via API | F17: Backend berjalan | G17: GET /api/books | H17: - | I17: Status 200, response array of book object | K17: Pass
A18: TC-017 | B18: View/List | C18: Positive | D18: Medium | E18: Ambil daftar buku saat data kosong | F18: Semua data dihapus | G18: GET /api/books | H18: - | I18: Status 200, response [] (bukan error) | K18: Not Executed | L18: Tidak dieksekusi untuk menghindari kehilangan data uji utama — cukup divalidasi secara logis bahwa endpoint mengembalikan array (terbukti dari TC-016), asumsi array kosong [] akan sama validnya
A19: TC-018 | B19: View/List | C19: Positive | D19: High | E19: Halaman Browse Library menampilkan daftar buku | F19: Frontend & backend berjalan | G19: Buka halaman Browse Library | H19: - | I19: Semua buku tampil dengan title, author, status | K19: Pass | L19: Semua buku tampil di Browse Library dengan title, author, status
A20: TC-019 | B20: View/List | C20: Positive | D20: Medium | E20: Label status ditampilkan sesuai data | F20: Ada buku dgn status berbeda | G20: Cek tampilan status tiap buku | H20: - | I20: Label unread/reading/completed sesuai data backend | J20: Status "read" dan "reading" tampil sebagai label teks sesuai data. Status "want-to-read" tidak punya label teks, digantikan tombol "+" tidak ada indikator visual status yang jelas untuk kategori ini | K20: Fail
A21: TC-020 | B21: View/List | C21: Negative | D21: High | E21: UI saat backend tidak dapat diakses | F21: Backend dimatikan | G21: Buka/refresh halaman | H21: - | I21: Muncul pesan error informatif, UI tidak blank/crash | J21: Saat backend mati, muncul pesan informatif "Failed to fetch books. Please try again later." di UI. Console menunjukkan network error yang tertangkap dengan baik (try/catch), tidak ada uncaught exception atau crash halaman | K21: Pass
A22: TC-021 | B22: Update Book | C22: Positive | D22: High | E22: Update title/author buku via API | F22: Ada buku valid | G22: PUT /api/books/<id> | H22: title baru | I22: Status 200, data ter-update | J22: 200 OK, title berhasil diupdate | K22: Pass
A23: TC-022 | B23: Update Book | C23: Positive | D23: High | E23: Update status unread -> reading | F23: Ada buku status unread | G23: PUT /api/books/<id> | H23: status="reading" | I23: Status 200, status berubah | J23: 200 OK, status berhasil berubah dari want-to-read ke reading | K23: Pass
A24: TC-023 | B24: Update Book | C24: Positive | D24: High | E24: Update status reading -> completed | F24: Ada buku status reading | G24: PUT /api/books/<id> | H24: status="completed" | I24: Status 200, status berubah | J24: 200 OK, status berhasil berubah dari reading ke read | K24: Pass
A25: TC-024 | B25: Update Book | C25: Negative | D25: High | E25: Update buku dengan ID tidak ada | F25: Backend berjalan | G25: PUT /api/books/999999 | H25: data valid | I25: Status 404, tidak membuat data baru | J25: 404 Not Found, response {"error": "Book not found"} | K25: Pass
A26: TC-025 | B26: Update Book | C26: Negative | D26: High | E26: Update dengan status tidak valid | F26: Ada buku valid | G26: PUT /api/books/<id> | H26: status="onhold" | I26: Ditolak (400), data lama tidak berubah | J26: 200 OK (harusnya 400), status "onhold" tersimpan meski bukan enum valid | K26: Fail
A27: TC-026 | B27: Update Book | C27: Negative | D27: Medium | E27: Update dengan title dikosongkan | F27: Ada buku valid | G27: PUT /api/books/<id> | H27: title="" | I27: Ditolak (400) | J27: 200 OK (harusnya 400), title:"" tersimpan (dieksekusi di id:1 tidak sengaja) | K27: Fail
A28: TC-027 | B28: Update Book | C28: Negative | D28: Medium | E28: Update dengan format ID tidak valid | F28: Backend berjalan | G28: PUT /api/books/abc | H28: data valid | I28: Status 400/404, bukan 500 error | J28: 404 Not Found, tidak ada 500 error | K28: Pass
A29: TC-028 | B29: Update Book | C29: Positive | D29: High | E29: Edit buku via UI, simpan perubahan | F29: Frontend & backend berjalan | G29: Klik edit, ubah data, save | H29: data baru | I29: Daftar buku ter-refresh menampilkan data terbaru | K29: Blocked | L29: Tidak ada form/UI untuk edit title/author buku. Klik pada kartu buku maupun halaman MyLibrary tidak membuka form edit.
A30: TC-029 | B30: Update Book | C30: Negative | D30: Medium | E30: Edit buku via UI, kosongkan title, coba save | F30: Frontend berjalan | G30: Hapus isi title, klik save | H30: title="" | I30: Validasi mencegah simpan / muncul pesan error | K30: Blocked | L30: Sama seperti TC-028, tidak ada form edit di UI sehingga skenario "kosongkan title lalu save" tidak bisa diuji.
A31: TC-030 | B31: Delete Book | C31: Positive | D31: High | E31: Hapus buku dengan ID valid via API | F31: Ada buku valid | G31: DELETE /api/books/<id> | H31: - | I31: Status 200/204, buku hilang dari GET list | J31: 200 OK, data berhasil terhapus dari list (terbukti dari pembersihan data sebelumnya) | K31: Pass
A32: TC-031 | B32: Delete Book | C32: Negative | D32: High | E32: Hapus buku dengan ID tidak ada | F32: Backend berjalan | G32: DELETE /api/books/999999 | H32: - | I32: Status 404 | J32: 404 Not Found, {"error": "Book not found"} | K32: Pass
A33: TC-032 | B33: Delete Book | C33: Negative | D33: Medium | E33: Hapus buku yang sama dua kali | F33: Ada buku valid | G33: DELETE dua kali berturut-turut | H33: - | I33: Panggilan kedua mengembalikan 404, bukan 200 | J33: Delete pertama: 200 OK data terhapus. Delete kedua: 404 Not Found, tidak ada error/crash | K33: Pass
A34: TC-033 | B34: Delete Book | C34: Positive | D34: High | E34: Hapus buku via UI | F34: Frontend & backend berjalan | G34: Klik delete, konfirmasi | H34: - | I34: Buku hilang dari daftar setelah konfirmasi | K34: Blocked | L34: Tidak ada tombol/elemen delete di UI (Browse Library maupun MyLibrary). Fitur delete hanya bisa diakses via API langsung.
A35: TC-034 | B35: Delete Book | C35: Negative | D35: Medium | E35: Batalkan konfirmasi delete | F35: Frontend berjalan | G35: Klik delete, lalu cancel | H35: - | I35: Buku tetap ada di daftar, tidak terhapus | K35: Blocked | L35: Sama seperti TC-033, tidak bisa diuji karena tidak ada tombol delete/dialog konfirmasi di UI.
A36: TC-035 | B36: General | C36: Negative | D36: Low | E36: Akses endpoint dengan method tidak didukung | F36: Backend berjalan | G36: PATCH /api/books | H36: - | I36: Status 405 Method Not Allowed | J36: 405 Method Not Allowed | K36: Pass
A37: TC-036 | B37: General | C37: Positive | D37: Medium | E37: CORS mengizinkan request dari frontend | F37: Frontend & backend berjalan | G37: Panggil API dari origin frontend | H37: - | I37: Header CORS mengizinkan, tidak ada error CORS di console | J37: Tidak ada CORS error di console selama testing UI, request dari frontend ke backend berhasil normal | K37: Pass
A38: TC-037 | B38: General | C38: Negative | D38: Low | E38: Data tidak persisten setelah restart backend | F38: Backend berjalan | G38: Tambah buku, restart backend, GET books | H38: - | I38: Dokumentasikan sebagai known behavior, bukan bug | J38: Setelah restart backend, semua data (termasuk hasil testing) tetap ada. Ternyata storage menggunakan file books.json, bukan in-memory seperti disebutkan README | K38: Fail
A39: TC-038 | B39: General | C39: Positive | D39: Low | E39: Tampilan responsif di layar kecil (mobile) | F39: Frontend berjalan | G39: Buka Browse Library dgn viewport mobile | H39: - | I39: Layout tetap rapi, tidak ada elemen terpotong | J39: Layout tetap rapi di viewport mobile (iPhone SE), tidak ada elemen terpotong/overflow | K39: Pass
A40: TC-039 | B40: General | C40: Negative | D40: Medium | E40: Kirim body JSON yang malformed | F40: Backend berjalan | G40: POST /api/books dengan JSON rusak | H40: {"title":"A", | I40: Status 400, bukan 500 | J40: 400 Bad Request untuk JSON malformed maupun body kosong, tidak ada 500 error/crash server | K40: Pass
...

Sheet Coverage Summary
A1: Module | B1: Total TC | C1: Executed | D1: Pass | E1: Fail | F1: Blocked | G1: Not Executed | H1: Coverage % | I1: Pass Rate %
A2: Add Book | B2: =COUNTIF('Test Cases'!B:B,A2) -> 15 | C2: =COUNTIFS('Test Cases'!B:B,A2,'Test Cases'!K:K,"<>Not Executed") -> 15 | D2: =COUNTIFS('Test Cases'!B:B,A2,'Test Cases'!K:K,"Pass") -> 7 | E2: =COUNTIFS('Test Cases'!B:B,A2,'Test Cases'!K:K,"Fail") -> 5 | F2: =COUNTIFS('Test Cases'!B:B,A2,'Test Cases'!K:K,"Blocked") -> 3 | G2: =COUNTIFS('Test Cases'!B:B,A2,'Test Cases'!K:K,"Not Executed") -> 0 | H2: =IFERROR(C2/B2,0) -> 1 | I2: =IFERROR(D2/C2,0) -> 0.46666667
A3: View/List | B3: =COUNTIF('Test Cases'!B:B,A3) -> 5 | C3: =COUNTIFS('Test Cases'!B:B,A3,'Test Cases'!K:K,"<>Not Executed") -> 4 | D3: =COUNTIFS('Test Cases'!B:B,A3,'Test Cases'!K:K,"Pass") -> 3 | E3: =COUNTIFS('Test Cases'!B:B,A3,'Test Cases'!K:K,"Fail") -> 1 | F3: =COUNTIFS('Test Cases'!B:B,A3,'Test Cases'!K:K,"Blocked") -> 0 | G3: =COUNTIFS('Test Cases'!B:B,A3,'Test Cases'!K:K,"Not Executed") -> 1 | H3: =IFERROR(C3/B3,0) -> 0.8 | I3: =IFERROR(D3/C3,0) -> 0.75
A4: Update Book | B4: =COUNTIF('Test Cases'!B:B,A4) -> 9 | C4: =COUNTIFS('Test Cases'!B:B,A4,'Test Cases'!K:K,"<>Not Executed") -> 9 | D4: =COUNTIFS('Test Cases'!B:B,A4,'Test Cases'!K:K,"Pass") -> 5 | E4: =COUNTIFS('Test Cases'!B:B,A4,'Test Cases'!K:K,"Fail") -> 2 | F4: =COUNTIFS('Test Cases'!B:B,A4,'Test Cases'!K:K,"Blocked") -> 2 | G4: =COUNTIFS('Test Cases'!B:B,A4,'Test Cases'!K:K,"Not Executed") -> 0 | H4: =IFERROR(C4/B4,0) -> 1 | I4: =IFERROR(D4/C4,0) -> 0.55555556
A5: Delete Book | B5: =COUNTIF('Test Cases'!B:B,A5) -> 5 | C5: =COUNTIFS('Test Cases'!B:B,A5,'Test Cases'!K:K,"<>Not Executed") -> 5 | D5: =COUNTIFS('Test Cases'!B:B,A5,'Test Cases'!K:K,"Pass") -> 3 | E5: =COUNTIFS('Test Cases'!B:B,A5,'Test Cases'!K:K,"Fail") -> 0 | F5: =COUNTIFS('Test Cases'!B:B,A5,'Test Cases'!K:K,"Blocked") -> 2 | G5: =COUNTIFS('Test Cases'!B:B,A5,'Test Cases'!K:K,"Not Executed") -> 0 | H5: =IFERROR(C5/B5,0) -> 1 | I5: =IFERROR(D5/C5,0) -> 0.6
A6: General | B6: =COUNTIF('Test Cases'!B:B,A6) -> 6 | C6: =COUNTIFS('Test Cases'!B:B,A6,'Test Cases'!K:K,"<>Not Executed") -> 6 | D6: =COUNTIFS('Test Cases'!B:B,A6,'Test Cases'!K:K,"Pass") -> 5 | E6: =COUNTIFS('Test Cases'!B:B,A6,'Test Cases'!K:K,"Fail") -> 1 | F6: =COUNTIFS('Test Cases'!B:B,A6,'Test Cases'!K:K,"Blocked") -> 0 | G6: =COUNTIFS('Test Cases'!B:B,A6,'Test Cases'!K:K,"Not Executed") -> 0 | H6: =IFERROR(C6/B6,0) -> 1 | I6: =IFERROR(D6/C6,0) -> 0.83333333
A7: TOTAL | B7: =SUM(B2:B6) -> 40 | C7: =SUM(C2:C6) -> 39 | D7: =SUM(D2:D6) -> 23 | E7: =SUM(E2:E6) -> 9 | F7: =SUM(F2:F6) -> 7 | G7: =SUM(G2:G6) -> 1 | H7: =IFERROR(C7/B7,0) -> 0.975 | I7: =IFERROR(D7/C7,0) -> 0.58974359

Sheet Bug Log
A1: Bug ID | B1: Related TC ID | C1: Title | D1: Severity | E1: Priority | F1: Environment | G1: Steps to Reproduce | H1: Expected Result | I1: Actual Result | J1: Status | K1: Reported By | L1: Date
A2: BUG-001 | B2: TC-007 | C2: Dokumentasi README tidak sesuai implementasi aktual (port, enum status, dan mekanisme storage) | D2: Minor | E2: Medium | F2: Local | G2: 1. Jalankan backend sesuai README (port 5000)\ 2. Backend ternyata jalan di port 5001\ 3. Cek response GET /api/books, field status berisi "read"/"want-to-read" 4. README menyatakan "Currently using in-memory storage" tapi ternyata data disimpan permanen di file books.json | H2: Port backend = 5000, nilai status = unread/reading/completed (sesuai README) Storage sebenarnya persisten via books.json, bukan in-memory | I2: Port backend = 5001, nilai status = read/reading/want-to-read | J2: Open | K2: [Daffa Arkantaqqy] | L2: [09/09/2026]
A3: BUG-002 | B3: TC-004, TC-005, TC-008, TC-026 | C3: POST /api/books tidak validasi required field, title/author null menyebabkan seluruh halaman Browse Library crash (uncaught TypeError) | D3: Critical | E3: High | F3: Local | G3: 1. POST /api/books tanpa title atau author → tersimpan sebagai null\ 2. Buka halaman Browse Library\ 3. Halaman crash, muncul error di console: Cannot read properties of null (reading 'toLowerCase') di BrowseLibrary.tsx:49 | H3: Request ditolak di backend (400) sehingga data null tidak pernah sampai ke frontend; atau minimal frontend melakukan null-check sebelum memanggil .toLowerCase() | I3: Backend menerima data null, frontend crash total (blank page) untuk semua pengguna, bukan cuma buku yang bermasalah | J3: Open | K3: [Daffa Arkantaqqy] | L3: [09/09/2026]
A4: BUG-003 | B4: TC-007,TC-025 | C4: POST dan PUT /api/books menerima nilai status di luar enum yang valid | D4: Major | E4: High | F4: Local | G4: 1. POST /api/books dengan status:"finished" (bukan read/reading/want-to-read)\ 2. Cek response 3. PUT /api/books/<id> dengan status:"onhold" juga diterima (200) tanpa validasi | H4: Ditolak, status 400 Bad Request | I4: Diterima, status 201 Created, tersimpan dengan status: "finished" yang tidak valid | J4: Open | K4: [Daffa Arkantaqqy] | L4: [09/09/2026]
A5: BUG-004 | B5: TC-010 | C5: POST /api/books tidak memvalidasi/mengonversi tipe data title — nilai number tersimpan apa adanya dan menyebabkan crash total di halaman Browse Library | D5: Critical | E5: High | F5: Local | G5: 1. POST /api/books dengan title: 12345 (number)\ 2. Data tersimpan tanpa validasi\ 3. Buka halaman Browse Library → seluruh halaman crash, console: book.title.toLowerCase is not a function | H5: Backend menolak (400) tipe data yang salah; atau minimal frontend melakukan null/type-check sebelum .toLowerCase() | I5: Data tersimpan, seluruh halaman Browse Library down untuk semua user | J5: Open | K5: [Daffa Arkantaqqy] | L5: [09/09/2026]
A6: OBSERVATION-001 | B6: TC-012–014, TC-028–029, TC-033–034 | C6: README menyebutkan fitur "Add, view, update, and delete books" tapi UI Browse Library/MyLibrary hanya menyediakan operasi View dan aksi terbatas (tombol "+" untuk set status want-to-read). Add, Update (edit bebas), dan Delete hanya bisa diakses via API langsung, tidak ada form/tombol di UI. | D6: Trival | E6: Low | F6: Local | G6: 1. Buka halaman Browse Library\ 2. Cari tombol/form untuk menambahkan buku baru dengan title/author bebas\ 3. Tidak ditemukan — tombol "+" yang ada berfungsi untuk hal lain (menambahkan buku existing ke My Library) | H6: Sesuai README ("Add, view, update, and delete books"), harusnya ada form UI untuk membuat buku baru | I6: Tidak ada form seperti itu di UI; fitur Add hanya bisa diakses lewat POST /api/books langsung | J6: Open | K6: [Daffa Arkantaqqy] | L6: [09/09/2026]
